<?xml version='1.0'?>
 <robot xmlns:controller="http://playerstage.sourceforge.net/gazebo/xmlschema/#controller" xmlns:interface="http://playerstage.sourceforge.net/gazebo/xmlschema/#interface" xmlns:sensor="http://playerstage.sourceforge.net/gazebo/xmlschema/#sensor" xmlns:xacro="http://ros.org/wiki/xacro"  name="my_robot">



  <link name="base_link">
  <inertial>
    <origin xyz="0 0 .285" rpy="0 0 0"/>       
    <inertia  ixx="13.7365" ixy="5.0948"  ixz="3.87399"  iyy="9.35242"  iyz="6.0809"  izz="12.09045"/>
    <mass value="14.130"/>
  </inertial>  

   <collision name='collision'>
          	<origin xyz="0 0 .285" rpy="0 0 0"/>
	          <geometry>
              <box size=".54 .76 .29">
                
              </box>
            </geometry>
            
           </collision>

           <visual name='visual'>
            <geometry>
              <box size=".54 .76 .29">
                
              </box>
            </geometry>
             
          </visual>           
      </link>


 <link name="left_wheel">
  <inertial>
    <origin xyz="-.29 -.17 -.155" rpy="0 1.5707 0"/>
    <mass value="2.238"/>
    <inertia  ixx="2.3018" ixy="2.303"  ixz="2.569"  iyy="1.326"  iyz="1.1105"  izz="1.083" />
  </inertial> 
  
  <collision name="collision">
   <geometry>
    <cylinder length=".05" radius="0.20">
              
    </cylinder>
   </geometry>
  </collision>
  <visual name="visual">
   <geometry>
    <cylinder length=".05" radius="0.20">
    </cylinder>
   </geometry>
  </visual>
 </link>

 <link name="right_wheel">
       <inertial>        
	  <origin xyz="0.29 -.17 -.155" rpy="0 1.5707 0"/>
          
         <inertia  ixx="2.3018" ixy="1.198"  ixz="1.336"  iyy="2.714"  iyz="1.1105"  izz="2.471" />

          <mass value="2.238"/>
       </inertial>
        <collision name="collision">
          <geometry>
            <cylinder length=".05" radius="0.20">
            </cylinder>
          </geometry>
        </collision>
        <visual name="visual">
          
           <geometry>
             <cylinder length=".05" radius="0.20">
            </cylinder>
          </geometry>
        </visual>
      </link>
   

<link name="front_ball"> 
   <inertial>
      <origin xyz="0.5 0.25 -.19" rpy="0 0 0"/>  
    <inertia  ixx=".7879" ixy=".4935"  ixz=".25869"  iyy=".5679"  iyz=".3233"  izz="1.01379"/>        <mass value="1.748"/>   
     </inertial>
      <visual>
      <geometry>
        <sphere radius="0.11"/>
      </geometry>
     </visual>
     <collision>
       <geometry>
        <sphere radius="0.11"/>
      </geometry>
    </collision>
</link>

<link name="camera_stand">
  <inertial>
    <origin xyz="0 -.396 .550" rpy="0 0 0"/>
    <inertia ixx="2.291" ixy=".4847" ixz="0.3279" iyy=".8303" iyz="9.90" izz="1.781"/>
    <mass value=".701"/>
  </inertial>
  <visual>
      <geometry>
        <box size="0.05 0.03 0.9"/>
      </geometry>
     </visual>
     <collision>
       <geometry>
        <box size="0.05 0.03 0.9"/>
      </geometry>
    </collision>
</link>
 <link name="camera_cam">
  <inertial>
    <origin xyz="0 -0.396 0.357" rpy="0 0 0"/>
    <inertia ixx=".174" ixy=".031" ixz=".014" iyy=".036" iyz=".065" izz=".152"/>
    <mass value="0.028"/>
  </inertial>
  <visual>
      <geometry>
        <box size="0.054 0.076 0.029"/>
      </geometry>
     </visual>
     <collision>
       <geometry>
        <box size="0.054 0.076 0.029"/>
      </geometry>
    </collision>
</link>

<gazebo reference="camera_cam">
    <sensor type="camera" name="camera1">
      <update_rate>30.0</update_rate>
      <camera name="head">
        <horizontal_fov>1.3962634</horizontal_fov>
        <image>
          <width>800</width>
          <height>800</height>
          <format>R8G8B8</format>
        </image>
        <clip>
          <near>0.02</near>
          <far>300</far>
        </clip>
        <noise>
          <type>gaussian</type>
          <!-- Noise is sampled independently per pixel on each frame.
               That pixel's noise value is added to each of its color
               channels, which at that point lie in the range [0,1]. -->
          <mean>0.0</mean>
          <stddev>0.007</stddev>
        </noise>
      </camera>
      <plugin name="camera_controller" filename="libgazebo_ros_camera.so">
        <alwaysOn>true</alwaysOn>
        <updateRate>0.0</updateRate>
        <cameraName>rrbot/camera1</cameraName>
        <imageTopicName>image_raw</imageTopicName>
        <cameraInfoTopicName>camera_info</cameraInfoTopicName>
        <frameName>camera_link</frameName>
        <hackBaseline>0.07</hackBaseline>
        <distortionK1>0.0</distortionK1>
        <distortionK2>0.0</distortionK2>
        <distortionK3>0.0</distortionK3>
        <distortionT1>0.0</distortionT1>
        <distortionT2>0.0</distortionT2>
      </plugin>
    </sensor>
  </gazebo>

<link name="gps_sensor">
  <inertial>
    <origin xyz="0 0.092 0.144" rpy="0 0 0"/>
    <inertia ixx=".032" ixy=".013" ixz=".007" iyy=".015" iyz=".014" izz=".030"/>
    <mass value="0.028"/>
  </inertial>
  <visual>
      <geometry>
        <box size="0.054 0.076 0.029"/>
      </geometry>
     </visual>
     <collision>
       <geometry>
        <box size="0.054 0.076 0.029"/>
      </geometry>
    </collision>
</link>



        <gazebo>
            <plugin name="gazebo_ros_gps" filename="libhector_gazebo_ros_gps.so">
                <updateRate>4.0</updateRate>
                <bodyName>sensor</bodyName>
                <frameId>sensor</frameId>
                <topicName>/gps/fix</topicName>
                <velocityTopicName>/gps/fix_velocity</velocityTopicName>
                <referenceLatitude>-30.06022459407145675</referenceLatitude>
                <referenceLongitude>-51.173913575780311191</referenceLongitude>
                <referenceHeading>90</referenceHeading>
                <referenceAltitude>10</referenceAltitude>
                <offset>0 0 0</offset>
                <drift>0.001 0.001 0.001</drift>
                <gaussianNoise>0.05 0.05 0.05</gaussianNoise>
                <velocityDrift>0.001 0.001 0.001</velocityDrift>
                <velocityGaussianNoise>0.5 0.5 0.5</velocityGaussianNoise>
<!--                <drift>0.001 0.001 0.001</drift>-->
<!--                <gaussianNoise>0.01 0.01 0.01</gaussianNoise>-->
<!--                <velocityDrift>0 0 0</velocityDrift>-->
<!--                <velocityGaussianNoise>0.05 0.05 0.05</velocityGaussianNoise>-->
            </plugin>
</gazebo>

<link name="imu_sensor">
  <inertial>
    <origin xyz="-.093 -.206 -.132" rpy="0 0 0"/>
    <inertia ixx=".001" ixy=".000" ixz=".0000" iyy=".001" iyz=".000" izz=".000"/>
    <mass value="0.028"/>
  </inertial>
  <visual>
      <geometry>
        <box size="0.054 0.076 0.029"/>
      </geometry>
     </visual>
     <collision>
       <geometry>
        <box size="0.054 0.076 0.029"/>
      </geometry>
    </collision>
</link>

<xacro:macro name="turtlebot_sim_imu">
  <gazebo>
    <controller:gazebo_ros_imu name="imu_controller" plugin="libgazebo_ros_imu.so">
      <alwaysOn>true</alwaysOn>
      <updateRate>30</updateRate>
      <bodyName>gyro_link</bodyName>
      <topicName>imu/data</topicName>
      <gaussianNoise>${0.0017*0.0017}</gaussianNoise>
      <xyzOffsets>0 0 0</xyzOffsets> 
      <rpyOffsets>0 0 0</rpyOffsets>
      <interface:position name="imu_position"/>
    </controller:gazebo_ros_imu>
  </gazebo>
</xacro:macro>


  
<link name="l_encoder">
  <inertial>
    <origin xyz="-.301 -.109 -.133" rpy="0 0 0"/>
    <inertia ixx=".001" ixy=".001" ixz=".0001" iyy=".001" iyz=".001" izz=".001"/>
    <mass value="0.028"/>
  </inertial>
  <visual>
      <geometry>
        <box size="0.054 0.076 0.029"/>
      </geometry>
     </visual>
     <collision>
       <geometry>
        <box size="0.054 0.076 0.029"/>
      </geometry>
    </collision>
</link>

<link name="r_encoder">
  <inertial>
    <origin xyz=".301 -.109 -.133" rpy="0 0 0"/>
    <inertia ixx=".001" ixy=".001" ixz=".0001" iyy=".001" iyz=".001" izz=".001"/>
    <mass value="0.028"/>
  </inertial>
  <visual>
      <geometry>
        <box size="0.054 0.076 0.029"/>
      </geometry>
     </visual>
     <collision>
       <geometry>
        <box size="0.054 0.076 0.029"/>
      </geometry>
    </collision>
</link>

<joint name="r_encoder" type="fixed">
      <limit effort="4" lower="0" upper="6.28" velocity="0"/>
      <origin xyz=".301 -.109 -.133" rpy="0 0 0"/>
      <parent link="base_link"/>
      <child link="r_encoder"/>
      <axis xyz="0 0 0"/>
</joint>

<link name="laser_scan">
  <inertial>
    <origin xyz="0.000 -.420 .581" rpy="0 0 0"/>
    <inertia ixx="1.640" ixy=".368" ixz=".274" iyy=".716" iyz=".785" izz="1.186"/>
    <mass value="0.028"/>
  </inertial>
  <visual>
      <geometry>
        <box size="0.054 0.076 0.029"/>
      </geometry>
     </visual>
     <collision>
       <geometry>
        <box size="0.054 0.076 0.029"/>
      </geometry>
    </collision>
</link>

<xacro:macro name="turtlebot_sim_kinect">
  <gazebo reference="kinect">
    <sensor:camera name="camera">
      <imageFormat>R8G8B8</imageFormat>
      <imageSize>640 480</imageSize>
      <hfov>60</hfov>
      <nearClip>0.05</nearClip>
      <farClip>3</farClip>
      <updateRate>20</updateRate>
      <baseline>0.1</baseline>
      <controller:gazebo_ros_openni_kinect name="kinect_camera_controller" plugin="libgazebo_ros_openni_kinect.so">
        <alwaysOn>true</alwaysOn>
        <updateRate>20</updateRate>
        <imageTopicName>/camera/image_raw</imageTopicName>
        <pointCloudTopicName>/camera/depth/points</pointCloudTopicName>
        <cameraInfoTopicName>/camera/camera_info</cameraInfoTopicName>
        <frameName>camera_depth_optical_frame</frameName>
        <distortion_k1>0.0</distortion_k1>
        <distortion_k2>0.0</distortion_k2>
        <distortion_k3>0.0</distortion_k3>
        <distortion_t1>0.0</distortion_t1>
        <distortion_t2>0.0</distortion_t2>
      </controller:gazebo_ros_openni_kinect>
    </sensor:camera>
  </gazebo>
</xacro:macro>


<link name="lidar">
  <inertial>
    <origin xyz="0.000 -.389 .296" rpy="0 0 0"/>
    <inertia ixx="0.389" ixy=".089" ixz=".090" iyy=".238" iyz=".194" izz="0.233"/>
    <mass value="0.028"/>
  </inertial>
  <visual>
      <geometry>
        <box size="0.054 0.076 0.029"/>
      </geometry>
     </visual>
     <collision>
       <geometry>
        <box size="0.054 0.076 0.029"/>
      </geometry>
    </collision>
</link>

<gazebo reference="lidar">
    <sensor type="ray" name="lidar">
      <visualize>true</visualize>
      <update_rate>10</update_rate>
      <ray>
        <!-- Use gaussian noise -->
        <!--
        <noise>
        <type>gaussian</type>
        <mean>0.0</mean>
        <stddev>0.02</stddev>
      </noise>
      -->
        <scan>
          <horizontal>
            <samples>100</samples>
            <resolution>3.6</resolution>
            <min_angle>-3.14159265359</min_angle>
            <max_angle>3.14159265359</max_angle>
          </horizontal>
        </scan>
        <range>
          <min>0.05</min>
          <max>30</max>
          <resolution>0.02</resolution>
        </range>
      </ray>
      <plugin name="lidar_plugin" filename="libgazebo_ros_laser.so">
        <topicName>/scan</topicName>
        <frameName>/lidar</frameName>
      </plugin>
    </sensor>
  </gazebo>


<joint name="Laser_scan" type="fixed">
      <limit effort="4" lower="0" upper="6.28" velocity="0"/>
      <origin xyz="0.000 -.420 .581" rpy="0 0 0"/>
      <parent link="base_link"/>
      <child link="Laser_scan"/>
      <axis xyz="0 0 0"/>
</joint>

<joint name="lidar" type="fixed">
      <limit effort="4" lower="0" upper="6.28" velocity="0"/>
      <origin xyz="0.000 -.389 .296" rpy="0 0 0"/>
      <parent link="base_link"/>
      <child link="lidar"/>
      <axis xyz="0 0 0"/>
</joint>

<joint name="l_encoder" type="fixed">
      <limit effort="4" lower="0" upper="6.28" velocity="0"/>
      <origin xyz="-.301 -.109 -.133" rpy="0 0 0"/>
      <parent link="base_link"/>
      <child link="l_encoder"/>
      <axis xyz="0 0 0"/>
</joint>


<joint name="imu_joint" type="fixed">
      <limit effort="4" lower="0" upper="6.28" velocity="0"/>
      <origin xyz="-.093 -.206 -.132" rpy="0 0 0"/>
      <parent link="base_link"/>
      <child link="imu_sensor"/>
      <axis xyz="0 0 0"/>
</joint>

<joint name="camera_joint" type="fixed">
      <limit effort="4" lower="0" upper="6.28" velocity="0"/>
      <origin xyz="0 -.357 1.486" rpy="0 0 0"/>
      <parent link="base_link"/>
      <child link="camera_cam"/>
      <axis xyz="0 0 0"/>
</joint>

<joint name="gps_joint" type="fixed">
      <limit effort="4" lower="0" upper="6.28" velocity="0"/>
      <origin xyz="0 .092 .144" rpy="0 0 0"/>
      <parent link="base_link"/>
      <child link="gps_sensor"/>
      <axis xyz="0 0 0"/>
</joint>
<joint type="fixed" name="camera_stand_hinge">
        <limit effort="4" lower="0" upper="6.28" velocity="10"/>
        <origin xyz="0 -.396 .550" rpy="0 0 0"/>
        <parent link="base_link"/>
        <child link="camera_stand"/>
        <axis xyz="0 0 0"/>
</joint>


  
<joint type="revolute" name="right_wheel_hinge">

	<limit effort="4" lower="0" upper="6.28" velocity="10"/>
        <origin xyz="0.29 -.17 -.155" rpy="0 1.5707 0"/>
        <parent link="base_link"/>
        <child link="right_wheel"/>
        <axis xyz="0 0 0"/>
</joint>

<joint type="revolute" name="left_wheel_hinge">

	<limit effort="4" lower="0" upper="6.28" velocity="10"/>
        <origin xyz="-.29 -.17 -.155" rpy="0 1.5707 0"/>
        <parent link="base_link"/>
        <child link="left_wheel"/>
        <axis xyz="0 0 0"/>
</joint>


<joint name="camera_rgb_joint" type="fixed">
      <origin xyz="-0.09 0 0.25"
              rpy="0 0 0"/>
      <parent link="base_link"/>
      <child link="camera_rgb_frame" />
    </joint>
    <link name="camera_rgb_frame"/>

<joint name="camera_rgb_optical_joint" type="fixed">
      <origin xyz="0 0 0" rpy="0 0 0" />
      <parent link="camera_rgb_frame" />
      <child link="camera_rgb_optical_frame" />
    </joint>
    <link name="camera_rgb_optical_frame"/>



<joint name="camera_depth_joint" type="fixed">
      <origin xyz="0 0 0" rpy="0 0 0" />
      <parent link="camera_rgb_frame" />
      <child link="camera_depth_frame" />
    </joint>
    <link name="camera_depth_frame"/>

<joint name="camera_depth_optical_joint" type="fixed">
      <origin xyz="0 0 0" rpy="0 0 0" />
      <parent link="camera_depth_frame" />
      <child link="camera_depth_optical_frame" />
    </joint>
    <link name="camera_depth_optical_frame"/>



    
    


 <joint name="base_footprint_to_front_ball" type="floating">
    <parent link="base_link"/>
    <child link="front_ball"/>
    <origin xyz="0 0.25 -.20" rpy="0 0 0" />
</joint>

<gazebo>
    <joint name='base_footprint_to_front_ball' type='ball'>
    <parent>base_link</parent>
    <child>front_ball</child>
    <origin xyz="0 0.25 -.19" rpy="0 0 0" />
     <physics>
        <ode>
          <limit>
            <cfm>0</cfm>
            <erp>0.2</erp>
          </limit>
          <suspension>
            <cfm>0</cfm>
            <erp>0.2</erp>
          </suspension>
        </ode>
      </physics>
    </joint>
</gazebo>

 
</robot>
